Workbook

Sheet groupe
A1: ETU003350 | B1: RANDRIANOMENA Harimalala Ericka

Sheet liste des taches
A1: Ligne | B1: Catégorie | C1: Module | D1: Page | E1: Description tâche | F1: Type | G1: Qui | H1: Estimation | I1: Temps passé | J1: Reste à faire | K1: Avancement | L1: Dépassement
A2: 1 | B2: Analyse et conception | C2: Gestion Cahier des charges | D2: cahierDesCharges | E2: Contexte | F2: Redaction | G2: ETU003350 | H2: 45 | I2: =detail_avancement!B2 -> 45 | J2: =MAX(0,H2-I2) -> 0 | K2: =IF(H2=0,0,MIN(1,I2/H2)) -> 1 | L2: =IF(I2>H2,I2-H2,0) -> 0
A3: 2 | B3: Analyse et conception | C3: Gestion Cahier des charges | D3: cahierDesCharges | E3: Problématique | F3: Redaction | G3: ETU003350 | H3: 30 | I3: =detail_avancement!B3 -> 30 | J3: =MAX(0,H3-I3) -> 0 | K3: =IF(H3=0,0,MIN(1,I3/H3)) -> 1 | L3: =IF(I3>H3,I3-H3,0) -> 0
A4: 3 | B4: Analyse et conception | C4: Gestion Cahier des charges | D4: cahierDesCharges | E4: Objectifs général et spécifiques | F4: Redaction | G4: ETU003350 | H4: 45 | I4: =detail_avancement!B4 -> 45 | J4: =MAX(0,H4-I4) -> 0 | K4: =IF(H4=0,0,MIN(1,I4/H4)) -> 1 | L4: =IF(I4>H4,I4-H4,0) -> 0
A5: 4 | B5: Analyse et conception | C5: Gestion Cahier des charges | D5: cahierDesCharges | E5: Périmètre (inclus et exclu) | F5: Redaction | G5: ETU003350 | H5: 30 | I5: =detail_avancement!B5 -> 30 | J5: =MAX(0,H5-I5) -> 0 | K5: =IF(H5=0,0,MIN(1,I5/H5)) -> 1 | L5: =IF(I5>H5,I5-H5,0) -> 0
A6: 5 | B6: Analyse et conception | C6: Gestion Cahier des charges | D6: cahierDesCharges | E6: Parties prenantes et acteurs | F6: Redaction | G6: ETU003350 | H6: 45 | I6: =detail_avancement!B6 -> 45 | J6: =MAX(0,H6-I6) -> 0 | K6: =IF(H6=0,0,MIN(1,I6/H6)) -> 1 | L6: =IF(I6>H6,I6-H6,0) -> 0
A7: 6 | B7: Analyse et conception | C7: Gestion Cahier des charges | D7: cahierDesCharges | E7: Situation actuelle des données | F7: Redaction | G7: ETU003350 | H7: 45 | I7: =detail_avancement!B7 -> 45 | J7: =MAX(0,H7-I7) -> 0 | K7: =IF(H7=0,0,MIN(1,I7/H7)) -> 1 | L7: =IF(I7>H7,I7-H7,0) -> 0
A8: 7 | B8: Analyse et conception | C8: Gestion Cahier des charges | D8: cahierDesCharges | E8: Limites constatées | F8: Redaction | G8: ETU003350 | H8: 30 | I8: =detail_avancement!B8 -> 30 | J8: =MAX(0,H8-I8) -> 0 | K8: =IF(H8=0,0,MIN(1,I8/H8)) -> 1 | L8: =IF(I8>H8,I8-H8,0) -> 0
A9: 8 | B9: Analyse et conception | C9: Gestion Cahier des charges | D9: cahierDesCharges | E9: Benchmark : GBIF | F9: Redaction | G9: ETU003350 | H9: 30 | I9: =detail_avancement!B9 -> 30 | J9: =MAX(0,H9-I9) -> 0 | K9: =IF(H9=0,0,MIN(1,I9/H9)) -> 1 | L9: =IF(I9>H9,I9-H9,0) -> 0
A10: 9 | B10: Analyse et conception | C10: Gestion Cahier des charges | D10: cahierDesCharges | E10: Benchmark : Specify | F10: Redaction | G10: ETU003350 | H10: 30 | I10: =detail_avancement!B10 -> 30 | J10: =MAX(0,H10-I10) -> 0 | K10: =IF(H10=0,0,MIN(1,I10/H10)) -> 1 | L10: =IF(I10>H10,I10-H10,0) -> 0
A11: 10 | B11: Analyse et conception | C11: Gestion Cahier des charges | D11: cahierDesCharges | E11: Benchmark : KoboToolbox | F11: Redaction | G11: ETU003350 | H11: 30 | I11: =detail_avancement!B11 -> 30 | J11: =MAX(0,H11-I11) -> 0 | K11: =IF(H11=0,0,MIN(1,I11/H11)) -> 1 | L11: =IF(I11>H11,I11-H11,0) -> 0
A12: 11 | B12: Analyse et conception | C12: Gestion Cahier des charges | D12: cahierDesCharges | E12: Besoins fonctionnels BF-01 à BF-06 | F12: Redaction | G12: ETU003350 | H12: 60 | I12: =detail_avancement!B12 -> 60 | J12: =MAX(0,H12-I12) -> 0 | K12: =IF(H12=0,0,MIN(1,I12/H12)) -> 1 | L12: =IF(I12>H12,I12-H12,0) -> 0
A13: 12 | B13: Analyse et conception | C13: Gestion Cahier des charges | D13: cahierDesCharges | E13: Besoins fonctionnels BF-07 à BF-12 | F13: Redaction | G13: ETU003350 | H13: 60 | I13: =detail_avancement!B13 -> 60 | J13: =MAX(0,H13-I13) -> 0 | K13: =IF(H13=0,0,MIN(1,I13/H13)) -> 1 | L13: =IF(I13>H13,I13-H13,0) -> 0
... A923: 922 | B923: Gestion de projet | C923: Gestion Suivi | D923: bilanSemaine | E923: Bilan de la semaine 13 | F923: Gestion | G923: ETU003350 | H923: 15 | I923: =detail_avancement!B923 -> 0 | J923: =MAX(0,H923-I923) -> 15 | K923: =IF(H923=0,0,MIN(1,I923/H923)) -> 0 | L923: =IF(I923>H923,I923-H923,0) -> 0

Sheet Recap
A2: Qui | B2: SUM of Estimation | C2: SUM of Temps passé | D2: SUM of Reste à faire
A3: ETU003350 | B3: 26460 | C3: 0 | D3: 26460
A12: Avancement | B12: =avancement!D2 -> 0.1077368

Sheet avancement
A1: estimation total | B1: temps passé total | C1: reste à faire total | D1: avancement | E1: dépassement | F1: reste réel total
A2: =SUM('liste des taches'!H:H) -> 26460 | B2: =SUM('liste des taches'!I:I) -> 3675 | C2: =SUM('liste des taches'!J2:J1000) -> 22935 | D2: =AVERAGEIF('liste des taches'!H2:H1000,">0",'liste des taches'!K2:K1000) -> 0.1077368 | E2: =SUM('liste des taches'!L2:L1000)/SUM('liste des taches'!H2:H1000) -> 0.0056689342 | F2: =SUM('liste des taches'!J2:J1000) -> 22935
A3: =A2/60 -> 441 | C3: =C2/60 -> 382.25 | D3: heure | F3: =F2/60 -> 382.25

Sheet detail_avancement
A1: Ligne | B1: Total | D1: avant 14 oct
A2: 1 | B2: =SUM(C2:CZ2) -> 45 | D2: 45
A3: 2 | B3: =SUM(C3:CZ3) -> 30 | D3: 30
A4: 3 | B4: =SUM(C4:CZ4) -> 45 | D4: 45
A5: 4 | B5: =SUM(C5:CZ5) -> 30 | D5: 30
A6: 5 | B6: =SUM(C6:CZ6) -> 45 | D6: 45
A7: 6 | B7: =SUM(C7:CZ7) -> 45 | D7: 45
A8: 7 | B8: =SUM(C8:CZ8) -> 30 | D8: 30
A9: 8 | B9: =SUM(C9:CZ9) -> 30 | D9: 30
A10: 9 | B10: =SUM(C10:CZ10) -> 30 | D10: 30
A11: 10 | B11: =SUM(C11:CZ11) -> 30 | D11: 30
A12: 11 | B12: =SUM(C12:CZ12) -> 60 | D12: 60
A13: 12 | B13: =SUM(C13:CZ13) -> 60 | D13: 60
... A23: 22 | B23: =SUM(C23:CZ23) -> 30 | D23: 30
A24: 23 | B24: =SUM(C24:CZ24) -> 0
A25: 24 | B25: =SUM(C25:CZ25) -> 0
A26: 25 | B26: =SUM(C26:CZ26) -> 30 | D26: 30
A27: 26 | B27: =SUM(C27:CZ27) -> 30 | D27: 30
A28: 27 | B28: =SUM(C28:CZ28) -> 30 | D28: 30
A29: 28 | B29: =SUM(C29:CZ29) -> 30 | D29: 30
A30: 29 | B30: =SUM(C30:CZ30) -> 45 | D30: 45
A31: 30 | B31: =SUM(C31:CZ31) -> 30 | D31: 30
A32: 31 | B32: =SUM(C32:CZ32) -> 15 | D32: 15
A33: 32 | B33: =SUM(C33:CZ33) -> 0
A34: 33 | B34: =SUM(C34:CZ34) -> 0
A35: 34 | B35: =SUM(C35:CZ35) -> 45 | D35: 45
A36: 35 | B36: =SUM(C36:CZ36) -> 30 | D36: 30
A37: 36 | B37: =SUM(C37:CZ37) -> 30 | D37: 30
A38: 37 | B38: =SUM(C38:CZ38) -> 45 | D38: 45
A39: 38 | B39: =SUM(C39:CZ39) -> 30 | D39: 30
A40: 39 | B40: =SUM(C40:CZ40) -> 45 | D40: 45
A41: 40 | B41: =SUM(C41:CZ41) -> 60 | D41: 60
A42: 41 | B42: =SUM(C42:CZ42) -> 30 | D42: 30
A43: 42 | B43: =SUM(C43:CZ43) -> 45 | D43: 45
A44: 43 | B44: =SUM(C44:CZ44) -> 45 | D44: 45
A45: 44 | B45: =SUM(C45:CZ45) -> 45 | D45: 45
A46: 45 | B46: =SUM(C46:CZ46) -> 45 | D46: 45
... A57: 56 | B57: =SUM(C57:CZ57) -> 30 | D57: 30
A58: 57 | B58: =SUM(C58:CZ58) -> 0
A59: 58 | B59: =SUM(C59:CZ59) -> 30 | D59: 30
...
